Workbook

Sheet Assumptions
A1: TDF VILLAGE MODEL - MASTER ASSUMPTIONS
A3: SEASON ALLOCATION
A4: Commercial Months (Adjustable) | B4: 5 | C4: months
A5: Commercial Days | B5: =B4*30.5 -> 152.5 | C5: days
A6: Community Months | B6: =12-B4 -> 7
A7: Community Days | B7: =365-B5 -> 212.5 | C7: days
A10: HOSPITALITY ROOMS
A11: Private Suites | B11: 12 | C11: units
A12: Studios | B12: 4 | C12: units
A13: Total Licensed | B13: =SUM(B11:B12) -> 16 | C13: units
A14: ADR High Season | B14: 165 | C14: EUR
A15: ADR Low Season | B15: 85 | C15: EUR
A16: Actual ADR | B16: =if(B93<50%, B14*2/3+B15*1/3,B14) -> 138.33333 | C16: EUR | D16: Commercial period primarily in high season
A17: Dorm beds | B17: 4 | C17: units | D17: Not counted (volunteers)
A18: House | B18: 1 | C18: unit | D18: Not counted (team)
A19: OTA Commission | B19: 0.18 | C19: %
A20: Net ADR (after OTA) | B20: =B16*(1-B19) -> 113.43333 | C20: EUR
A21: Commercial Occupancy Y1 | B21: 0.55 | C21: %
A22: Token Holder Stay Rate | B22: 0.9 | C22: % | D22: Token utilization rate
A25: UNIQUE ACCOMMODATIONS
A26: Glamping Big | B26: 6 | C26: units
A27: Glamping Small | B27: 3 | C27: units
A28: Treehouse | B28: 1 | C28: unit
A29: Silo Cabins | B29: 3 | C29: units
A30: Camping Spots | B30: 6 | C30: units
A31: Total Unofficial | B31: =SUM(B26:B30) -> 19 | C31: units
A33: Glamping Big Price | B33: 90 | C33: EUR/night
A34: Glamping Small Price | B34: 50 | C34: EUR/night
A35: Treehouse Price | B35: 120 | C35: EUR/night
A36: Silo Cabin Price | B36: 90 | C36: EUR/night
A37: Camping Price | B37: 20 | C37: EUR/night
A39: Guest Occupancy | B39: 0.4 | C39: %
A40: Seasonal Days (Glamping/Camp) | B40: 180 | C40: days
A41: Year-round Days (Tree/Silo) | B41: 365 | C41: days
A44: RESTAURANT
A45: Seats | B45: 30
A46: Meals served | B46: =B45*1.2 -> 36
A47: Lunch Covers/Day (Commercial) | B47: 15
A48: Dinner Covers/Day (Commercial) | B48: 25
A49: Food Cost % (Commercial) | B49: 0.3
...

Sheet Debt Stack
A1: DEBT STACK
A3: Category | B3: Principal | C3: Rate | D3: Term | E3: Priority | F3: Interest Type | G3: Conversion
A4: Bank Mortgage | B4: 700000 | C4: 0.045 | D4: 15 | E4: Senior | F4: Cash-paid | G4: None
A5: 2024 Debt | B5: 400000 | C5: 0.07 | D5: 4 | E5: Subordinated | F5: Accrued | G5: 0.6
A6: 2026 Debt | B6: 450000 | C6: 0.05 | D6: 4 | E6: Subordinated | F6: Accrued | G6: 0.3
A7: Co-Housing Deposits | B7: 500000 | C7: 0.02 | D7: 4 | E7: Subordinated | F7: Accrued | G7: 0.9
A8: TOTAL DEBT | B8: =SUM(B4:B7) -> 2050000
A10: 2024/2025 contracts | B10: Principal | C10: Maturity
A11: Private | B11: 50000 | C11: 46082
A12: Private | B12: =50000*6 -> 300000 | C12: 46752
A13: Private | B13: 50000 | C13: 47118
A14: Shareholder debt | B14: 30000 | C14: 46752
A16: YEARLY DEBT & CONVERSION SCHEDULE
B17: 2025 | C17: 2026 | D17: 2027 | E17: 2028 | F17: 2029 | G17: 2030 | H17: 2031 | I17: 2032 | J17: 2033 | K17: 2034 | L17: 2035 | M17: 2036 | N17: 2037 | O17: 2038 | P17: 2039 | Q17: 2040
A18: BANK MORTGAGE
A19: Opening Balance | B19: 0 | C19: 700000 | D19: =C22 -> 653333.33 | E19: =D22 -> 606666.67 | F19: =E22 -> 560000 | G19: =F22 -> 513333.33 | H19: =G22 -> 466666.67 | I19: =H22 -> 420000 | J19: =I22 -> 373333.33 | K19: =J22 -> 326666.67 | ... Q19: =P22 -> 46666.667
A20: Principal Payment | B20: 0 | C20: =-$B$4 / 15 -> -46666.667 | D20: =-$B$4 / 15 -> -46666.667 | E20: =-$B$4 / 15 -> -46666.667 | F20: =-$B$4 / 15 -> -46666.667 | G20: =-$B$4 / 15 -> -46666.667 | H20: =-$B$4 / 15 -> -46666.667 | I20: =-$B$4 / 15 -> -46666.667 | J20: =-$B$4 / 15 -> -46666.667 | ... Q20: =-$B$4 / 15 -> -46666.667
A21: Interest | B21: 0 | C21: =-C19*$C$4 -> -31500 | D21: =-D19*$C$4 -> -29400 | E21: =-E19*$C$4 -> -27300 | F21: =-F19*$C$4 -> -25200 | G21: =-G19*$C$4 -> -23100 | H21: =-H19*$C$4 -> -21000 | I21: =-I19*$C$4 -> -18900 | J21: =-J19*$C$4 -> -16800 | ... Q21: =-Q19*$C$4 -> -2100
A22: Closing Balance | B22: 0 | C22: =C19+C20 -> 653333.33 | D22: =D19+D20 -> 606666.67 | E22: =E19+E20 -> 560000 | F22: =F19+F20 -> 513333.33 | G22: =G19+G20 -> 466666.67 | H22: =H19+H20 -> 420000 | I22: =I19+I20 -> 373333.33 | J22: =J19+J20 -> 326666.67 | ... Q22: =Q19+Q20 -> 0
A24: 2024 Debt
A25: Opening Balance | B25: =B5-B14 -> 370000 | C25: =B29 -> 363111 | D25: =C29 -> 258528.77 | E25: =D29 -> 226625.78 | F25: =E29 -> 0 | G25: =F29 -> 0 | H25: =G29 -> 0 | I25: =H29 -> 0 | J25: =I29 -> 0 | ... Q25: =P29 -> 0
A26: Accrued Interest | B26: =B25*$C$5 -> 25900 | C26: =C25*$C$5 -> 25417.77 | D26: =D25*$C$5 -> 18097.014 | E26: =E25*$C$5 -> 15863.805 | F26: =F25*$C$5 -> 0 | G26: =G25*$C$5 -> 0 | H26: =H25*$C$5 -> 0 | I26: =I25*$C$5 -> 0 | ... Q26: =Q25*$C$5 -> 0
A27: Converted to Tokens | B27: -32600 | C27: -80000 | D27: -50000 | E27: -30000 | F27: 0 | G27: 0 | H27: 0 | I27: 0 | J27: 0 | K27: 0 | L27: 0 | M27: 0 | N27: 0 | O27: 0 | P27: 0 | Q27: 0
A28: Cash Repaid | B28: -189 | C28: -50000 | D28: 0 | E28: =(E25+E26+E27)*-1 -> -212489.59 | F28: 0 | G28: 0 | H28: 0 | I28: =(I25+I26+I27)*-1 -> 0 | J28: 0 | K28: 0 | L28: 0 | M28: =(M25+M26+M27)*-1 -> 0 | N28: 0 | O28: 0 | P28: 0 | Q28: =(Q25+Q26+Q27)*-1 -> 0
A29: Closing Balance | B29: =SUM(B25:B28) -> 363111 | C29: =SUM(C25:C28) -> 258528.77 | D29: =SUM(D25:D28) -> 226625.78 | E29: =ROUND(SUM(E25:E28),0) -> 0 | F29: =SUM(F25:F28) -> 0 | G29: =SUM(G25:G28) -> 0 | H29: =SUM(H25:H28) -> 0 | I29: =SUM(I25:I28) -> 0 | J29: =SUM(J25:J28) -> 0 | K29: =SUM(K25:K28) -> 0 | L29: =SUM(L25:L28) -> 0 | M29: =SUM(M25:M28) -> 0 | ... Q29: =SUM(Q25:Q28) -> 0
A31: 2026 Debt
A32: Opening Balance | B32: 0 | C32: =B6 -> 450000 | D32: =C36 -> 472500 | E32: =D36 -> 446125 | F32: =E36 -> 393431.25 | G32: =F36 -> 238102.81 | H32: =G36 -> 0 | I32: =H36 -> 0 | J32: =I36 -> 0 | K32: =J36 -> 0 | ... Q32: =P36 -> 0
A33: Accrued Interest | B33: 0 | C33: =C32*$C$6 -> 22500 | D33: =D32*$C$6 -> 23625 | E33: =E32*$C$6 -> 22306.25 | F33: =F32*$C$6 -> 19671.562 | G33: =G32*$C$6 -> 11905.141 | H33: =H32*$C$6 -> 0 | I33: =I32*$C$6 -> 0 | J33: =J32*$C$6 -> 0 | ... Q33: =Q32*$C$6 -> 0
A34: Converted to Tokens | B34: 0 | C34: 0 | D34: -50000 | E34: -25000 | F34: -25000 | G34: 0 | H34: 0 | I34: 0 | J34: 0 | K34: 0 | L34: 0 | M34: 0 | N34: 0 | O34: 0 | P34: 0 | Q34: 0
A35: Cash Repaid | B35: 0 | C35: 0 | D35: 0 | E35: -50000 | F35: -150000 | G35: =-(G32+G33) -> -250007.95 | H35: 0 | I35: 0 | J35: 0 | K35: 0 | L35: 0 | M35: 0 | N35: 0 | O35: 0 | P35: 0 | Q35: 0
A36: Closing Balance | B36: 0 | C36: =SUM(C32:C35) -> 472500 | D36: =SUM(D32:D35) -> 446125 | E36: =SUM(E32:E35) -> 393431.25 | F36: =SUM(F32:F35) -> 238102.81 | G36: =SUM(G32:G35) -> 0 | H36: =SUM(H32:H35) -> 0 | I36: =SUM(I32:I35) -> 0 | J36: =SUM(J32:J35) -> 0 | ... L36: =SUM(L32:L35) -> 0 | M36: 0 | N36: =SUM(N32:N35) -> 0 | O36: =SUM(O32:O35) -> 0 | P36: =SUM(P32:P35) -> 0 | Q36: =SUM(Q32:Q35) -> 0
A38: CO-HOUSING DEPOSITS
A39: Opening Balance | B39: 0 | C39: 500000 | D39: =C43 -> 460000 | E39: =D43 -> 219200 | F39: =E43 -> 0 | G39: =F43 -> 0 | H39: =G43 -> 0 | I39: =H43 -> 0 | J39: =I43 -> 0 | K39: =J43 -> 0 | ... Q39: =P43 -> 0
A40: Accrued Interest | B40: 0 | C40: =C39*$C$7 -> 10000 | D40: =D39*$C$7 -> 9200 | E40: =E39*$C$7 -> 4384 | F40: =F39*$C$7 -> 0 | G40: =G39*$C$7 -> 0 | H40: =H39*$C$7 -> 0 | I40: =I39*$C$7 -> 0 | J40: =J39*$C$7 -> 0 | ... Q40: =Q39*$C$7 -> 0
A41: Converted to Tokens | B41: 0 | C41: -50000 | D41: -250000 | E41: =-(E40+E39) -> -223584 | F41: 0 | G41: 0 | H41: 0 | I41: =-(I40+I39) -> 0 | J41: 0 | K41: 0 | L41: 0 | M41: 0 | N41: 0 | O41: 0 | P41: 0 | Q41: 0
A42: Cash Repaid | B42: 0 | C42: 0 | D42: 0 | E42: 0 | F42: 0 | G42: 0 | H42: 0 | I42: 0 | J42: 0 | K42: 0 | L42: 0 | M42: 0 | N42: 0 | O42: 0 | P42: 0 | Q42: 0
A43: Closing Balance | B43: 0 | C43: =SUM(C39:C42) -> 460000 | D43: =SUM(D39:D42) -> 219200 | E43: =SUM(E39:E42) -> 0 | F43: =SUM(F39:F42) -> 0 | G43: =SUM(G39:G42) -> 0 | H43: =SUM(H39:H42) -> 0 | I43: =SUM(I39:I42) -> 0 | J43: =SUM(J39:J42) -> 0 | ... Q43: =SUM(Q39:Q42) -> 0
A45: TOTALS
A46: Total Debt Outstanding | B46: =B43+B36+B29+B22 -> 363111 | C46: =C43+C36+C29+C22 -> 1844362.1 | D46: =D43+D36+D29+D22 -> 1498617.5 | E46: =E43+E36+E29+E22 -> 953431.25 | F46: =F43+F36+F29+F22 -> 751436.15 | G46: =G43+G36+G29+G22 -> 466666.67 | H46: =H43+H36+H29+H22 -> 420000 | I46: =I43+I36+I29+I22 -> 373333.33 | ... Q46: =Q43+Q36+Q29+Q22 -> 0
A47: Total private loans | B47: =B43+B36+B29 -> 363111 | C47: =C43+C36+C29 -> 1191028.8 | D47: =D43+D36+D29 -> 891950.78 | E47: =E43+E36+E29 -> 393431.25 | F47: =F43+F36+F29 -> 238102.81 | G47: =G43+G36+G29 -> 0 | H47: =H43+H36+H29 -> 0 | I47: =I43+I36+I29 -> 0 | ... Q47: =Q43+Q36+Q29 -> 0
...

Sheet Revenue
A1: REVENUE MODEL
A3: COMMERCIAL SEASON
A4: Metric | B4: 2028 | C4: 2029 | D4: 2030 | E4: 2031 | F4: 2032 | G4: 2033 | H4: 2034 | I4: 2035 | J4: 2036 | K4: 2037 | L4: 2038 | M4: 2039 | N4: 2040
A5: Commercial Days | B5: =Assumptions!$B$5 -> 152.5 | C5: =B5 -> 152.5 | D5: =B5 -> 152.5 | E5: =B5 -> 152.5 | F5: =B5 -> 152.5 | G5: =B5 -> 152.5 | H5: =B5 -> 152.5 | I5: =B5 -> 152.5 | J5: =B5 -> 152.5 | K5: =B5 -> 152.5 | L5: =E5 -> 152.5 | M5: =E5 -> 152.5 | N5: =E5 -> 152.5
A6: Room Nights Available | B6: =B5*Assumptions!$B$13 -> 2440 | C6: =C5*Assumptions!$B$13 -> 2440 | D6: =D5*Assumptions!$B$13 -> 2440 | E6: =E5*Assumptions!$B$13 -> 2440 | F6: =F5*Assumptions!$B$13 -> 2440 | G6: =G5*Assumptions!$B$13 -> 2440 | H6: =H5*Assumptions!$B$13 -> 2440 | I6: =I5*Assumptions!$B$13 -> 2440 | ... N6: =N5*Assumptions!$B$13 -> 2440
A7: Occupancy | B7: =Assumptions!$B$21 -> 0.55 | C7: =MIN(B7+0.05,0.75) -> 0.6 | D7: =MIN(C7+0.05,0.78) -> 0.65 | E7: =MIN(D7+0.03,0.8) -> 0.68 | F7: =E7 -> 0.68 | G7: =F7 -> 0.68 | H7: =G7 -> 0.68 | I7: =H7 -> 0.68 | J7: =I7 -> 0.68 | K7: =J7 -> 0.68 | L7: =K7 -> 0.68 | M7: =L7 -> 0.68 | N7: =M7 -> 0.68
A8: Occupied Nights | B8: =ROUND(B6*B7,0) -> 1342 | C8: =ROUND(C6*C7,0) -> 1464 | D8: =ROUND(D6*D7,0) -> 1586 | E8: =ROUND(E6*E7,0) -> 1659 | F8: =ROUND(F6*F7,0) -> 1659 | G8: =ROUND(G6*G7,0) -> 1659 | H8: =ROUND(H6*H7,0) -> 1659 | I8: =ROUND(I6*I7,0) -> 1659 | ... N8: =ROUND(N6*N7,0) -> 1659
A9: Net ADR | B9: =Assumptions!$B$20 -> 113.43333 | C9: =B9*(1+Assumptions!$B$58) -> 115.702 | D9: =C9*(1+Assumptions!$B$58) -> 118.01604 | E9: =D9*(1+Assumptions!$B$58) -> 120.37636 | F9: =E9*(1+Assumptions!$B$58) -> 122.78389 | G9: =F9*(1+Assumptions!$B$58) -> 125.23957 | H9: =G9*(1+Assumptions!$B$58) -> 127.74436 | I9: =H9*(1+Assumptions!$B$58) -> 130.29924 | J9: =I9*(1+Assumptions!$B$58) -> 132.90523 | ... N9: =M9*(1+Assumptions!$B$58) -> 143.86089
A10: Accommodation Revenue | B10: =B8*B9 -> 152227.53 | C10: =C8*C9 -> 169387.73 | D10: =D8*D9 -> 187173.44 | E10: =E8*E9 -> 199704.38 | F10: =F8*F9 -> 203698.47 | G10: =G8*G9 -> 207772.44 | H10: =H8*H9 -> 211927.89 | I10: =I8*I9 -> 216166.45 | ... N10: =N8*N9 -> 238665.22
A11: Restaurant Revenue | B11: =(Assumptions!B46*Assumptions!B5*Assumptions!B47)+(Assumptions!B46*Assumptions!B48*Assumptions!B5) -> 219600 | C11: =B11*(1+Assumptions!$B$59) -> 237168 | D11: =C11*(1+Assumptions!$B$59) -> 256141.44 | E11: =D11*(1+Assumptions!$B$59) -> 276632.76 | F11: =E11*(1+Assumptions!$B$59) -> 298763.38 | G11: =F11*(1+Assumptions!$B$59) -> 322664.45 | H11: =G11*(1+Assumptions!$B$59) -> 348477.6 | I11: =H11*(1+Assumptions!$B$59) -> 376355.81 | J11: =I11*(1+Assumptions!$B$59) -> 406464.27 | ... N11: =M11*(1+Assumptions!$B$59) -> 552990.16
A12: COMMERCIAL TOTAL | B12: =B10+B11 -> 371827.53 | C12: =C10+C11 -> 406555.73 | D12: =D10+D11 -> 443314.88 | E12: =E10+E11 -> 476337.14 | F12: =F10+F11 -> 502461.85 | G12: =G10+G11 -> 530436.89 | H12: =H10+H11 -> 560405.49 | I12: =I10+I11 -> 592522.26 | ... N12: =N10+N11 -> 791655.38
A14: COMMUNITY SEASON
A15: Metric | B15: 2028 | C15: 2029 | D15: 2030 | E15: 2031 | F15: 2032 | G15: 2033 | H15: 2034 | I15: 2035 | J15: 2036 | K15: 2037 | L15: 2038 | M15: 2039 | N15: 2040
A16: Community Days | B16: =Assumptions!$B$7 -> 212.5 | C16: =B16 -> 212.5 | D16: =B16 -> 212.5 | E16: =B16 -> 212.5 | F16: =B16 -> 212.5 | G16: =B16 -> 212.5 | H16: =B16 -> 212.5 | I16: =B16 -> 212.5 | J16: =B16 -> 212.5 | K16: =B16 -> 212.5 | L16: =E16 -> 212.5 | M16: =E16 -> 212.5 | N16: =E16 -> 212.5
A17: Room Nights Available | B17: =B16*Assumptions!$B$13 -> 3400 | C17: =C16*Assumptions!$B$13 -> 3400 | D17: =D16*Assumptions!$B$13 -> 3400 | E17: =E16*Assumptions!$B$13 -> 3400 | F17: =F16*Assumptions!$B$13 -> 3400 | G17: =G16*Assumptions!$B$13 -> 3400 | H17: =H16*Assumptions!$B$13 -> 3400 | I17: =I16*Assumptions!$B$13 -> 3400 | ... N17: =N16*Assumptions!$B$13 -> 3400
A18: Token Holder Nights | B18: =ROUND(B17*Assumptions!$B$22,0) -> 3060 | C18: =ROUND(C17*Assumptions!$B$22,0) -> 3060 | D18: =ROUND(D17*Assumptions!$B$22,0) -> 3060 | E18: =ROUND(E17*Assumptions!$B$22,0) -> 3060 | F18: =ROUND(F17*Assumptions!$B$22,0) -> 3060 | G18: =ROUND(G17*Assumptions!$B$22,0) -> 3060 | H18: =ROUND(H17*Assumptions!$B$22,0) -> 3060 | I18: =ROUND(I17*Assumptions!$B$22,0) -> 3060 | ... N18: =ROUND(N17*Assumptions!$B$22,0) -> 3060
A19: Guest Nights (40% of unused nights) | B19: =ROUND((B17-B18)*0.4,0) -> 136 | C19: =ROUND((C17-C18)*0.4,0) -> 136 | D19: =ROUND((D17-D18)*0.4,0) -> 136 | E19: =ROUND((E17-E18)*0.4,0) -> 136 | F19: =ROUND((F17-F18)*0.4,0) -> 136 | G19: =ROUND((G17-G18)*0.4,0) -> 136 | H19: =ROUND((H17-H18)*0.4,0) -> 136 | I19: =ROUND((I17-I18)*0.4,0) -> 136 | ... N19: =ROUND((N17-N18)*0.4,0) -> 136
A20: Utility Fees (co-housing + co-living) | B20: =(B18+B19)*Assumptions!B55+ 'Co-Housing'!$G$37 -> 69784 | C20: =B20*(1+Assumptions!$B$58) -> 71179.68 | D20: =C20*(1+Assumptions!$B$58) -> 72603.274 | E20: =D20*(1+Assumptions!$B$58) -> 74055.339 | F20: =E20*(1+Assumptions!$B$58) -> 75536.446 | G20: =F20*(1+Assumptions!$B$58) -> 77047.175 | H20: =G20*(1+Assumptions!$B$58) -> 78588.118 | I20: =H20*(1+Assumptions!$B$58) -> 80159.881 | J20: =I20*(1+Assumptions!$B$58) -> 81763.078 | ... N20: =M20*(1+Assumptions!$B$58) -> 88502.985
A21: Food revenue | B21: =(B18+B19)*Assumptions!$B$54 -> 44744 | C21: =B21*(1+Assumptions!$B$58) -> 45638.88 | D21: =C21*(1+Assumptions!$B$58) -> 46551.658 | E21: =D21*(1+Assumptions!$B$58) -> 47482.691 | F21: =E21*(1+Assumptions!$B$58) -> 48432.345 | G21: =F21*(1+Assumptions!$B$58) -> 49400.991 | H21: =G21*(1+Assumptions!$B$58) -> 50389.011 | I21: =H21*(1+Assumptions!$B$58) -> 51396.792 | J21: =I21*(1+Assumptions!$B$58) -> 52424.727 | ... N21: =M21*(1+Assumptions!$B$58) -> 56746.211
A22: Cafe | B22: =Assumptions!$B$7*(Assumptions!$B$52*Assumptions!$B$53) -> 21250 | C22: =B22*(1+Assumptions!$B$58) -> 21675 | D22: =C22*(1+Assumptions!$B$58) -> 22108.5 | E22: =D22*(1+Assumptions!$B$58) -> 22550.67 | F22: =E22*(1+Assumptions!$B$58) -> 23001.683 | G22: =F22*(1+Assumptions!$B$58) -> 23461.717 | H22: =G22*(1+Assumptions!$B$58) -> 23930.951 | I22: =H22*(1+Assumptions!$B$58) -> 24409.57 | J22: =I22*(1+Assumptions!$B$58) -> 24897.762 | ... N22: =M22*(1+Assumptions!$B$58) -> 26950.138
A23: COMMUNITY TOTAL | B23: =B21+B22+B20 -> 135778 | C23: =C21+C22+C20 -> 138493.56 | D23: =D21+D22+D20 -> 141263.43 | E23: =E21+E22+E20 -> 144088.7 | F23: =F21+F22+F20 -> 146970.47 | G23: =G21+G22+G20 -> 149909.88 | H23: =H21+H22+H20 -> 152908.08 | I23: =I21+I22+I20 -> 155966.24 | ... N23: =N21+N22+N20 -> 172199.33
A25: UNIQUE ACCOMMODATIONS
A26: Metric | B26: 2028 | C26: 2029 | D26: 2030 | E26: 2031 | F26: 2032 | G26: 2033 | H26: 2034 | I26: 2035 | J26: 2036 | K26: 2037 | L26: 2038 | M26: 2039 | N26: 2040
A27: Glamping Big (6 units, 180d) | B27: =ROUND(6*180*Assumptions!$B$39,0)*Assumptions!$B$33 -> 38880 | C27: =B27*(1+Assumptions!$B$59) -> 41990.4 | D27: =C27*(1+Assumptions!$B$59) -> 45349.632 | E27: =D27*(1+Assumptions!$B$59) -> 48977.603 | F27: =E27*(1+Assumptions!$B$59) -> 52895.811 | G27: =F27*(1+Assumptions!$B$59) -> 57127.476 | H27: =G27*(1+Assumptions!$B$59) -> 61697.674 | I27: =H27*(1+Assumptions!$B$59) -> 66633.488 | J27: =I27*(1+Assumptions!$B$59) -> 71964.167 | ... N27: =M27*(1+Assumptions!$B$59) -> 97906.454
A28: Glamping Small (3 units, 180d) | B28: =ROUND(3*180*Assumptions!$B$39,0)*Assumptions!$B$34 -> 10800 | C28: =B28*(1+Assumptions!$B$59) -> 11664 | D28: =C28*(1+Assumptions!$B$59) -> 12597.12 | E28: =D28*(1+Assumptions!$B$59) -> 13604.89 | F28: =E28*(1+Assumptions!$B$59) -> 14693.281 | G28: =F28*(1+Assumptions!$B$59) -> 15868.743 | H28: =G28*(1+Assumptions!$B$59) -> 17138.243 | I28: =H28*(1+Assumptions!$B$59) -> 18509.302 | J28: =I28*(1+Assumptions!$B$59) -> 19990.046 | ... N28: =M28*(1+Assumptions!$B$59) -> 27196.237
A29: Treehouse (1 unit, 365d) | B29: =ROUND(1*365*Assumptions!$B$39,0)*Assumptions!$B$35 -> 17520 | C29: =B29*(1+Assumptions!$B$59) -> 18921.6 | D29: =C29*(1+Assumptions!$B$59) -> 20435.328 | E29: =D29*(1+Assumptions!$B$59) -> 22070.154 | F29: =E29*(1+Assumptions!$B$59) -> 23835.767 | G29: =F29*(1+Assumptions!$B$59) -> 25742.628 | H29: =G29*(1+Assumptions!$B$59) -> 27802.038 | I29: =H29*(1+Assumptions!$B$59) -> 30026.201 | J29: =I29*(1+Assumptions!$B$59) -> 32428.297 | ... N29: =M29*(1+Assumptions!$B$59) -> 44118.34
A30: Silo Cabins (3 units, 365d) | B30: =ROUND(3*365*Assumptions!$B$39,0)*Assumptions!$B$36 -> 39420 | C30: =B30*(1+Assumptions!$B$59) -> 42573.6 | D30: =C30*(1+Assumptions!$B$59) -> 45979.488 | E30: =D30*(1+Assumptions!$B$59) -> 49657.847 | F30: =E30*(1+Assumptions!$B$59) -> 53630.475 | G30: =F30*(1+Assumptions!$B$59) -> 57920.913 | H30: =G30*(1+Assumptions!$B$59) -> 62554.586 | I30: =H30*(1+Assumptions!$B$59) -> 67558.953 | J30: =I30*(1+Assumptions!$B$59) -> 72963.669 | ... N30: =M30*(1+Assumptions!$B$59) -> 99266.266
A31: Camping (6 spots, 180d) | B31: =ROUND(6*180*Assumptions!$B$39,0)*Assumptions!$B$37 -> 8640 | C31: =B31*(1+Assumptions!$B$59) -> 9331.2 | D31: =C31*(1+Assumptions!$B$59) -> 10077.696 | E31: =D31*(1+Assumptions!$B$59) -> 10883.912 | F31: =E31*(1+Assumptions!$B$59) -> 11754.625 | G31: =F31*(1+Assumptions!$B$59) -> 12694.995 | H31: =G31*(1+Assumptions!$B$59) -> 13710.594 | I31: =H31*(1+Assumptions!$B$59) -> 14807.442 | J31: =I31*(1+Assumptions!$B$59) -> 15992.037 | ... N31: =M31*(1+Assumptions!$B$59) -> 21756.99
A32: UNIQUE TOTAL | B32: =SUM(B27:B31) -> 115260 | C32: =SUM(C27:C31) -> 124480.8 | D32: =SUM(D27:D31) -> 134439.26 | E32: =SUM(E27:E31) -> 145194.41 | F32: =SUM(F27:F31) -> 156809.96 | G32: =SUM(G27:G31) -> 169354.75 | H32: =SUM(H27:H31) -> 182903.13 | I32: =SUM(I27:I31) -> 197535.39 | ... N32: =SUM(N27:N31) -> 290244.29
A34: OTHER REVENUE
A35: Metric | B35: 2028 | C35: 2029 | D35: 2030 | E35: 2031 | F35: 2032 | G35: 2033 | H35: 2034 | I35: 2035 | J35: 2036 | K35: 2037 | L35: 2038 | M35: 2039 | N35: 2040
A36: Events & Retreats | B36: 20000 | C36: =B36*1.08 -> 21600 | D36: =C36*1.08 -> 23328 | E36: =D36*1.08 -> 25194.24 | F36: =E36*1.08 -> 27209.779 | G36: =F36*1.08 -> 29386.562 | H36: =G36*1.08 -> 31737.486 | I36: =H36*1.08 -> 34276.485 | J36: =I36*1.08 -> 37018.604 | ... N36: =M36*1.08 -> 50363.402
A37: Donations | B37: 10000 | C37: 10000 | D37: 10000 | E37: 10000 | F37: 10000 | G37: 10000 | H37: 10000 | I37: 10000 | J37: 10000 | K37: 10000 | L37: 10000 | M37: 10000 | N37: 10000
A38: OTHER TOTAL | B38: =SUM(B36:B37) -> 30000 | C38: =SUM(C36:C37) -> 31600 | D38: =SUM(D36:D37) -> 33328 | E38: =SUM(E36:E37) -> 35194.24 | F38: =SUM(F36:F37) -> 37209.779 | G38: =SUM(G36:G37) -> 39386.562 | H38: =SUM(H36:H37) -> 41737.486 | I38: =SUM(I36:I37) -> 44276.485 | ... N38: =SUM(N36:N37) -> 60363.402
A40: TOTAL REVENUE SUMMARY
A41: Metric | B41: 2028 | C41: 2029 | D41: 2030 | E41: 2031 | F41: 2032 | G41: 2033 | H41: 2034 | I41: 2035 | J41: 2036 | K41: 2037 | L41: 2038 | M41: 2039 | N41: 2040
A42: Commercial | B42: =B12 -> 371827.53 | C42: =C12 -> 406555.73 | D42: =D12 -> 443314.88 | E42: =E12 -> 476337.14 | F42: =F12 -> 502461.85 | G42: =G12 -> 530436.89 | H42: =H12 -> 560405.49 | I42: =I12 -> 592522.26 | ... N42: =N12 -> 791655.38
A43: Community | B43: =B23 -> 135778 | C43: =C23 -> 138493.56 | D43: =D23 -> 141263.43 | E43: =E23 -> 144088.7 | F43: =F23 -> 146970.47 | G43: =G23 -> 149909.88 | H43: =H23 -> 152908.08 | I43: =I23 -> 155966.24 | ... N43: =N23 -> 172199.33
A44: Unique Accommodations | B44: =B32 -> 115260 | C44: =C32 -> 124480.8 | D44: =D32 -> 134439.26 | E44: =E32 -> 145194.41 | F44: =F32 -> 156809.96 | G44: =G32 -> 169354.75 | H44: =H32 -> 182903.13 | I44: =I32 -> 197535.39 | ... N44: =N32 -> 290244.29
A45: Other Revenue | B45: =B38 -> 30000 | C45: =C38 -> 31600 | D45: =D38 -> 33328 | E45: =E38 -> 35194.24 | F45: =F38 -> 37209.779 | G45: =G38 -> 39386.562 | H45: =H38 -> 41737.486 | I45: =I38 -> 44276.485 | ... N45: =N38 -> 60363.402
...

Sheet Costs
A1: COST MODEL
A3: Metric | B3: 2028 | C3: 2029 | D3: 2030 | E3: 2031 | F3: 2032 | G3: 2033 | H3: 2034 | I3: 2035 | J3: 2036 | K3: 2037 | L3: 2038 | M3: 2039 | N3: 2040
A4: STAFF COSTS
A5: Total Staff (from Assumptions) | B5: =Assumptions!$E$80 -> 218913.75 | C5: =B5*(1+Assumptions!$B$58) -> 223292.02 | D5: =C5*(1+Assumptions!$B$58) -> 227757.87 | E5: =D5*(1+Assumptions!$B$58) -> 232313.02 | F5: =E5*(1+Assumptions!$B$58) -> 236959.28 | G5: =F5*(1+Assumptions!$B$58) -> 241698.47 | H5: =G5*(1+Assumptions!$B$58) -> 246532.44 | I5: =H5*(1+Assumptions!$B$58) -> 251463.09 | J5: =I5*(1+Assumptions!$B$58) -> 256492.35 | ... N5: =M5*(1+Assumptions!$B$58) -> 277635.57
A7: COST OF GOODS SOLD
A8: Food Cost (Commercial) | B8: =Revenue!B11*Assumptions!B49 -> 65880 | C8: =B8*(1+Assumptions!$B$60) -> 66868.2 | D8: =C8*(1+Assumptions!$B$60) -> 67871.223 | E8: =D8*(1+Assumptions!$B$60) -> 68889.291 | F8: =E8*(1+Assumptions!$B$60) -> 69922.631 | G8: =F8*(1+Assumptions!$B$60) -> 70971.47 | H8: =G8*(1+Assumptions!$B$60) -> 72036.042 | I8: =H8*(1+Assumptions!$B$60) -> 73116.583 | J8: =I8*(1+Assumptions!$B$60) -> 74213.332 | ... N8: =M8*(1+Assumptions!$B$60) -> 78767.325
A9: Food Cost (Community) | B9: =Revenue!B21*Assumptions!B51 -> 31320.8 | C9: =B9*(1+Assumptions!$B$60) -> 31790.612 | D9: =C9*(1+Assumptions!$B$60) -> 32267.471 | E9: =D9*(1+Assumptions!$B$60) -> 32751.483 | F9: =E9*(1+Assumptions!$B$60) -> 33242.755 | G9: =F9*(1+Assumptions!$B$60) -> 33741.397 | H9: =G9*(1+Assumptions!$B$60) -> 34247.518 | I9: =H9*(1+Assumptions!$B$60) -> 34761.231 | J9: =I9*(1+Assumptions!$B$60) -> 35282.649 | ... N9: =M9*(1+Assumptions!$B$60) -> 37447.718
A10: Consumables | B10: 12000 | C10: =B10*(1+Assumptions!$B$60) -> 12180 | D10: =C10*(1+Assumptions!$B$60) -> 12362.7 | E10: =D10*(1+Assumptions!$B$60) -> 12548.14 | F10: =E10*(1+Assumptions!$B$60) -> 12736.363 | G10: =F10*(1+Assumptions!$B$60) -> 12927.408 | H10: =G10*(1+Assumptions!$B$60) -> 13121.319 | I10: =H10*(1+Assumptions!$B$60) -> 13318.139 | J10: =I10*(1+Assumptions!$B$60) -> 13517.911 | ... N10: =M10*(1+Assumptions!$B$60) -> 14347.418
A11: Total COGS | B11: =SUM(B8:B10) -> 109200.8 | C11: =SUM(C8:C10) -> 110838.81 | D11: =SUM(D8:D10) -> 112501.39 | E11: =SUM(E8:E10) -> 114188.92 | F11: =SUM(F8:F10) -> 115901.75 | G11: =SUM(G8:G10) -> 117640.28 | H11: =SUM(H8:H10) -> 119404.88 | I11: =SUM(I8:I10) -> 121195.95 | ... N11: =SUM(N8:N10) -> 130562.46
A13: OPERATING EXPENSES
A14: Water, Electricity | B14: =300*12+400*12 -> 8400 | C14: =B14*(1+Assumptions!$B$60) -> 8526 | D14: =C14*(1+Assumptions!$B$60) -> 8653.89 | E14: =D14*(1+Assumptions!$B$60) -> 8783.6984 | F14: =E14*(1+Assumptions!$B$60) -> 8915.4538 | G14: =F14*(1+Assumptions!$B$60) -> 9049.1856 | H14: =G14*(1+Assumptions!$B$60) -> 9184.9234 | I14: =H14*(1+Assumptions!$B$60) -> 9322.6973 | J14: =I14*(1+Assumptions!$B$60) -> 9462.5377 | ... N14: =M14*(1+Assumptions!$B$60) -> 10043.193
A15: Insurance | B15: 17000 | C15: =B15*(1+Assumptions!$B$60) -> 17255 | D15: =C15*(1+Assumptions!$B$60) -> 17513.825 | E15: =D15*(1+Assumptions!$B$60) -> 17776.532 | F15: =E15*(1+Assumptions!$B$60) -> 18043.18 | G15: =F15*(1+Assumptions!$B$60) -> 18313.828 | H15: =G15*(1+Assumptions!$B$60) -> 18588.535 | I15: =H15*(1+Assumptions!$B$60) -> 18867.364 | J15: =I15*(1+Assumptions!$B$60) -> 19150.374 | ... N15: =M15*(1+Assumptions!$B$60) -> 20325.509
A16: Maintenance | B16: 15000 | C16: =B16*(1+Assumptions!$B$60) -> 15225 | D16: =C16*(1+Assumptions!$B$60) -> 15453.375 | E16: =D16*(1+Assumptions!$B$60) -> 15685.176 | F16: =E16*(1+Assumptions!$B$60) -> 15920.453 | G16: =F16*(1+Assumptions!$B$60) -> 16159.26 | H16: =G16*(1+Assumptions!$B$60) -> 16401.649 | I16: =H16*(1+Assumptions!$B$60) -> 16647.674 | J16: =I16*(1+Assumptions!$B$60) -> 16897.389 | ... N16: =M16*(1+Assumptions!$B$60) -> 17934.273
A17: Marketing | B17: 12000 | C17: =B17*(1+Assumptions!$B$60) -> 12180 | D17: =C17*(1+Assumptions!$B$60) -> 12362.7 | E17: =D17*(1+Assumptions!$B$60) -> 12548.14 | F17: =E17*(1+Assumptions!$B$60) -> 12736.363 | G17: =F17*(1+Assumptions!$B$60) -> 12927.408 | H17: =G17*(1+Assumptions!$B$60) -> 13121.319 | I17: =H17*(1+Assumptions!$B$60) -> 13318.139 | J17: =I17*(1+Assumptions!$B$60) -> 13517.911 | ... N17: =M17*(1+Assumptions!$B$60) -> 14347.418
A18: Accounting & Legal | B18: 15000 | C18: =B18*(1+Assumptions!$B$60) -> 15225 | D18: =C18*(1+Assumptions!$B$60) -> 15453.375 | E18: =D18*(1+Assumptions!$B$60) -> 15685.176 | F18: =E18*(1+Assumptions!$B$60) -> 15920.453 | G18: =F18*(1+Assumptions!$B$60) -> 16159.26 | H18: =G18*(1+Assumptions!$B$60) -> 16401.649 | I18: =H18*(1+Assumptions!$B$60) -> 16647.674 | J18: =I18*(1+Assumptions!$B$60) -> 16897.389 | ... N18: =M18*(1+Assumptions!$B$60) -> 17934.273
A19: Other OpEx | B19: 11000 | C19: =B19*(1+Assumptions!$B$60) -> 11165 | D19: =C19*(1+Assumptions!$B$60) -> 11332.475 | E19: =D19*(1+Assumptions!$B$60) -> 11502.462 | F19: =E19*(1+Assumptions!$B$60) -> 11674.999 | G19: =F19*(1+Assumptions!$B$60) -> 11850.124 | H19: =G19*(1+Assumptions!$B$60) -> 12027.876 | I19: =H19*(1+Assumptions!$B$60) -> 12208.294 | J19: =I19*(1+Assumptions!$B$60) -> 12391.418 | ... N19: =M19*(1+Assumptions!$B$60) -> 13151.8
A20: Total OpEx | B20: =SUM(B14:B19) -> 78400 | C20: =SUM(C14:C19) -> 79576 | D20: =SUM(D14:D19) -> 80769.64 | E20: =SUM(E14:E19) -> 81981.185 | F20: =SUM(F14:F19) -> 83210.902 | G20: =SUM(G14:G19) -> 84459.066 | H20: =SUM(H14:H19) -> 85725.952 | I20: =SUM(I14:I19) -> 87011.841 | ... N20: =SUM(N14:N19) -> 93736.465
A22: DEPRECIATION | B22: 78000 | C22: 78000 | D22: 70000 | E22: 65000 | F22: 60000 | G22: 50000 | H22: 45000 | I22: 45000 | J22: 45000 | K22: 45000 | L22: 45000 | M22: 45000 | N22: 45000
A24: FINANCING COSTS
A25: Bank Interest (5%) | B25: ='Debt Stack'!E50 -> -27300 | C25: ='Debt Stack'!F50 -> -25200 | D25: ='Debt Stack'!G50 -> -23100 | E25: ='Debt Stack'!H50 -> -21000 | F25: ='Debt Stack'!I50 -> -18900 | G25: ='Debt Stack'!J50 -> -16800 | H25: ='Debt Stack'!K50 -> -14700 | I25: ='Debt Stack'!L50 -> -12600 | ... N25: ='Debt Stack'!Q50 -> -2100
A26: Private Loans Interest | B26: ='Debt Stack'!E48 -> -42554.055 | C26: ='Debt Stack'!F48 -> -19671.562 | D26: ='Debt Stack'!G48 -> -11905.141 | E26: ='Debt Stack'!H48 -> 0 | F26: ='Debt Stack'!I48 -> 0 | G26: ='Debt Stack'!J48 -> 0 | H26: ='Debt Stack'!K48 -> 0 | I26: ='Debt Stack'!L48 -> 0 | ... N26: ='Debt Stack'!Q48 -> 0
A27: Total Financing | B27: =SUM(B25:B26) -> -69854.055 | C27: =SUM(C25:C26) -> -44871.562 | D27: =SUM(D25:D26) -> -35005.141 | E27: =SUM(E25:E26) -> -21000 | F27: =SUM(F25:F26) -> -18900 | G27: =SUM(G25:G26) -> -16800 | H27: =SUM(H25:H26) -> -14700 | I27: =SUM(I25:I26) -> -12600 | ... N27: =SUM(N25:N26) -> -2100
A29: TOTAL COSTS | B29: =B5+B11+B20+B22+B27 -> 414660.5 | C29: =C5+C11+C20+C22+C27 -> 446835.27 | D29: =D5+D11+D20+D22+D27 -> 456023.76 | E29: =E5+E11+E20+E22+E27 -> 472483.12 | F29: =F5+F11+F20+F22+F27 -> 477171.93 | G29: =G5+G11+G20+G22+G27 -> 476997.81 | H29: =H5+H11+H20+H22+H27 -> 481963.27 | I29: =I5+I11+I20+I22+I27 -> 492070.88 | ... N29: =N5+N11+N20+N22+N27 -> 544834.49

Sheet PL
A1: PROFIT & LOSS 2028-2037
A3: Metric | B3: 2028 | C3: 2029 | D3: 2030 | E3: 2031 | F3: 2032 | G3: 2033 | H3: 2034 | I3: 2035 | J3: 2036 | K3: 2037 | L3: 2038 | M3: 2039 | N3: 2040
A4: Total Revenue | B4: =Revenue!B46 -> 652865.53 | C4: =Revenue!C46 -> 701130.09 | D4: =Revenue!D46 -> 752345.57 | E4: =Revenue!E46 -> 800814.48 | F4: =Revenue!F46 -> 843452.06 | G4: =Revenue!G46 -> 889088.08 | H4: =Revenue!H46 -> 937954.19 | I4: =Revenue!I46 -> 990300.37 | ... N4: =Revenue!N46 -> 1314462.4
A5: COGS | B5: =Costs!B11 -> 109200.8 | C5: =Costs!C11 -> 110838.81 | D5: =Costs!D11 -> 112501.39 | E5: =Costs!E11 -> 114188.92 | F5: =Costs!F11 -> 115901.75 | G5: =Costs!G11 -> 117640.28 | H5: =Costs!H11 -> 119404.88 | I5: =Costs!I11 -> 121195.95 | ... N5: =Costs!N11 -> 130562.46
A6: Gross Profit | B6: =B4-B5 -> 543664.73 | C6: =C4-C5 -> 590291.28 | D6: =D4-D5 -> 639844.18 | E6: =E4-E5 -> 686625.57 | F6: =F4-F5 -> 727550.31 | G6: =G4-G5 -> 771447.81 | H6: =H4-H5 -> 818549.31 | I6: =I4-I5 -> 869104.42 | ... N6: =N4-N5 -> 1183899.9
A8: Staff Costs | B8: =Costs!B5 -> 218913.75 | C8: =Costs!C5 -> 223292.02 | D8: =Costs!D5 -> 227757.87 | E8: =Costs!E5 -> 232313.02 | F8: =Costs!F5 -> 236959.28 | G8: =Costs!G5 -> 241698.47 | H8: =Costs!H5 -> 246532.44 | I8: =Costs!I5 -> 251463.09 | ... N8: =Costs!N5 -> 277635.57
A9: Operating Expenses | B9: =Costs!B20 -> 78400 | C9: =Costs!C20 -> 79576 | D9: =Costs!D20 -> 80769.64 | E9: =Costs!E20 -> 81981.185 | F9: =Costs!F20 -> 83210.902 | G9: =Costs!G20 -> 84459.066 | H9: =Costs!H20 -> 85725.952 | I9: =Costs!I20 -> 87011.841 | ... N9: =Costs!N20 -> 93736.465
A10: EBITDA | B10: =B6-B8-B9 -> 246350.98 | C10: =C6-C8-C9 -> 287423.25 | D10: =D6-D8-D9 -> 331316.67 | E10: =E6-E8-E9 -> 372331.36 | F10: =F6-F8-F9 -> 407380.12 | G10: =G6-G8-G9 -> 445290.27 | H10: =H6-H8-H9 -> 486290.92 | I10: =I6-I8-I9 -> 530629.49 | ... N10: =N6-N8-N9 -> 812527.91
A11: EBITDA Margin | B11: =B10/B4 -> 0.37733801 | C11: =C10/C4 -> 0.40994283 | D11: =D10/D4 -> 0.44037831 | E11: =E10/E4 -> 0.46494084 | F11: =F10/F4 -> 0.48299144 | G11: =G10/G4 -> 0.50083932 | H11: =H10/H4 -> 0.51845914 | I11: =I10/I4 -> 0.53582681 | ... N11: =N10/N4 -> 0.61814466
A13: Depreciation | B13: =Costs!B22 -> 78000 | C13: =Costs!C22 -> 78000 | D13: =Costs!D22 -> 70000 | E13: =Costs!E22 -> 65000 | F13: =Costs!F22 -> 60000 | G13: =Costs!G22 -> 50000 | H13: =Costs!H22 -> 45000 | I13: =Costs!I22 -> 45000 | ... N13: =Costs!N22 -> 45000
A14: EBIT | B14: =B10-B13 -> 168350.98 | C14: =C10-C13 -> 209423.25 | D14: =D10-D13 -> 261316.67 | E14: =E10-E13 -> 307331.36 | F14: =F10-F13 -> 347380.12 | G14: =G10-G13 -> 395290.27 | H14: =H10-H13 -> 441290.92 | I14: =I10-I13 -> 485629.49 | ... N14: =N10-N13 -> 767527.91
A16: Financing Costs | B16: =Costs!B27 -> -69854.055 | C16: =Costs!C27 -> -44871.562 | D16: =Costs!D27 -> -35005.141 | E16: =Costs!E27 -> -21000 | F16: =Costs!F27 -> -18900 | G16: =Costs!G27 -> -16800 | H16: =Costs!H27 -> -14700 | I16: =Costs!I27 -> -12600 | ... N16: =Costs!N27 -> -2100
A17: EBT | B17: =B14-B16 -> 238205.04 | C17: =C14-C16 -> 254294.81 | D17: =D14-D16 -> 296321.82 | E17: =E14-E16 -> 328331.36 | F17: =F14-F16 -> 366280.12 | G17: =G14-G16 -> 412090.27 | H17: =H14-H16 -> 455990.92 | I17: =I14-I16 -> 498229.49 | ... N17: =N14-N16 -> 769627.91
A18: Tax (21%) | B18: =MAX(0,B17*0.21) -> 50023.058 | C18: =MAX(0,C17*0.21) -> 53401.911 | D18: =MAX(0,D17*0.21) -> 62227.581 | E18: =MAX(0,E17*0.21) -> 68949.586 | F18: =MAX(0,F17*0.21) -> 76918.826 | G18: =MAX(0,G17*0.21) -> 86538.958 | H18: =MAX(0,H17*0.21) -> 95758.094 | I18: =MAX(0,I17*0.21) -> 104628.19 | ... N18: =MAX(0,N17*0.21) -> 161621.86
A19: NET INCOME | B19: =B17-B18 -> 188181.98 | C19: =C17-C18 -> 200892.9 | D19: =D17-D18 -> 234094.23 | E19: =E17-E18 -> 259381.77 | F19: =F17-F18 -> 289361.3 | G19: =G17-G18 -> 325551.32 | H19: =H17-H18 -> 360232.83 | I19: =I17-I18 -> 393601.3 | ... N19: =N17-N18 -> 608006.05
A20: Net Margin | B20: =B19/B4 -> 0.28824003 | C20: =C19/C4 -> 0.28652729 | D20: =D19/D4 -> 0.31115254 | E20: =E19/E4 -> 0.32389746 | F20: =F19/F4 -> 0.34306787 | G20: =G19/G4 -> 0.36616318 | H20: =H19/H4 -> 0.38406228 | I20: =I19/I4 -> 0.39745648 | ... N20: =N19/N4 -> 0.46255111

Sheet Cash Flow
A1: CASH FLOW STATEMENT
A3: Metric | B3: 2026 | C3: 2027 | D3: 2028 | E3: 2029 | F3: 2030 | G3: 2031 | H3: 2032 | I3: 2033 | J3: 2034 | K3: 2035 | L3: 2036 | M3: 2037 | N3: 2038 | O3: 2039 | P3: 2040
A4: OPERATING ACTIVITIES
A5: Net Income | B5: -10000 | C5: 50000 | D5: =PL!B19 -> 188181.98 | E5: =PL!C19 -> 200892.9 | F5: =PL!D19 -> 234094.23 | G5: =PL!E19 -> 259381.77 | H5: =PL!F19 -> 289361.3 | I5: =PL!G19 -> 325551.32 | J5: =PL!H19 -> 360232.83 | K5: =PL!I19 -> 393601.3 | ... P5: =PL!N19 -> 608006.05
A6: Add: Depreciation | B6: 0 | C6: 0 | D6: =PL!B13 -> 78000 | E6: =PL!C13 -> 78000 | F6: =PL!D13 -> 70000 | G6: =PL!E13 -> 65000 | H6: =PL!F13 -> 60000 | I6: =PL!G13 -> 50000 | J6: =PL!H13 -> 45000 | K6: =PL!I13 -> 45000 | ... P6: =PL!N13 -> 45000
A7: Working Capital Changes | B7: 0 | C7: 0 | D7: 0 | E7: 0 | F7: 0 | G7: 0 | H7: 0 | I7: 0 | J7: 0 | K7: 0 | L7: 0 | M7: 0 | N7: 0 | O7: 0 | P7: 0
A8: Operating Cash Flow | B8: =SUM(B5:B7) -> -10000 | C8: =SUM(C5:C7) -> 50000 | D8: =SUM(D5:D7) -> 266181.98 | E8: =SUM(E5:E7) -> 278892.9 | F8: =SUM(F5:F7) -> 304094.23 | G8: =SUM(G5:G7) -> 324381.77 | H8: =SUM(H5:H7) -> 349361.3 | I8: =SUM(I5:I7) -> 375551.32 | ... P8: =SUM(P5:P7) -> 653006.05
A10: INVESTING ACTIVITIES
A11: Building Purchase (from Sam) | B11: -200000 | C11: 0 | D11: 0 | E11: 0 | F11: 0 | G11: 0 | H11: 0 | I11: 0 | J11: 0 | K11: 0 | L11: 0 | M11: 0 | N11: 0 | O11: 0 | P11: 0
A12: Construction CapEx | B12: -850000 | C12: -200000 | D12: -50000 | E12: -50000 | F12: -50000 | G12: -50000 | H12: -50000 | I12: -50000 | J12: -50000 | K12: -50000 | L12: -50000 | M12: -50000 | N12: -50000 | O12: -50000 | P12: -50000
A13: Equipment & FF&E | B13: -100000 | C13: -50000 | D13: 0 | E13: 0 | F13: 0 | G13: 0 | H13: 0 | I13: 0 | J13: 0 | K13: 0 | L13: 0 | M13: 0 | N13: 0 | O13: 0 | P13: 0
A14: Investing Cash Flow | B14: =Sum(B11:B13) -> -1150000 | C14: =Sum(C11:C13) -> -250000 | D14: =Sum(D11:D13) -> -50000 | E14: =Sum(E11:E13) -> -50000 | F14: =Sum(F11:F13) -> -50000 | G14: =Sum(G11:G13) -> -50000 | H14: =Sum(H11:H13) -> -50000 | I14: =Sum(I11:I13) -> -50000 | ... P14: =Sum(P11:P13) -> -50000
A16: FINANCING ACTIVITIES
A17: Bank Loan Drawdown | B17: 700000 | I17: 0 | J17: 0 | K17: 0 | L17: 0 | M17: 0 | N17: 0 | O17: 0 | P17: 0
A18: Bank Loan Principal | B18: ='Debt Stack'!C20 -> -46666.667 | C18: ='Debt Stack'!D20 -> -46666.667 | D18: ='Debt Stack'!E20 -> -46666.667 | E18: ='Debt Stack'!F20 -> -46666.667 | F18: ='Debt Stack'!G20 -> -46666.667 | G18: ='Debt Stack'!H20 -> -46666.667 | H18: ='Debt Stack'!I20 -> -46666.667 | I18: ='Debt Stack'!J20 -> -46666.667 | ... P18: ='Debt Stack'!Q20 -> -46666.667
A19: Equity injection from token proceeds | B19: 150000 | C19: 250000 | D19: 250000 | E19: 200000 | F19: 0 | G19: 0 | H19: 0 | I19: 0 | J19: 0 | K19: 0 | L19: 0 | M19: 0 | N19: 0 | O19: 0 | P19: 0
A20: Private Loan | B20: ='Debt Stack'!C32 -> 450000
A21: Private Loan Principal | B21: ='Debt Stack'!C49 -> -50000 | C21: ='Debt Stack'!D49 -> 0 | D21: ='Debt Stack'!E49 -> -262489.59 | E21: ='Debt Stack'!F49 -> -150000 | F21: ='Debt Stack'!G49 -> -250007.95 | G21: ='Debt Stack'!H49 -> 0 | H21: ='Debt Stack'!I49 -> 0 | I21: ='Debt Stack'!J49 -> 0 | ... P21: ='Debt Stack'!Q49 -> 0
A22: Financing Cash Flow | B22: =SUM(B17:B21) -> 1203333.3 | C22: =SUM(C17:C21) -> 203333.33 | D22: =SUM(D17:D21) -> -59156.255 | E22: =SUM(E17:E21) -> 3333.3333 | F22: =SUM(F17:F21) -> -296674.62 | G22: =SUM(G17:G21) -> -46666.667 | H22: =SUM(H17:H21) -> -46666.667 | I22: =SUM(I17:I21) -> -46666.667 | ... P22: =SUM(P17:P21) -> -46666.667
A24: NET CASH FLOW | B24: =B22+B14+B8 -> 43333.333 | C24: =C22+C14+C8 -> 3333.3333 | D24: =D22+D14+D8 -> 157025.72 | E24: =E22+E14+E8 -> 232226.24 | F24: =F22+F14+F8 -> -42580.385 | G24: =G22+G14+G8 -> 227715.11 | H24: =H22+H14+H8 -> 252694.63 | I24: =I22+I14+I8 -> 278884.65 | ... P24: =P22+P14+P8 -> 556339.38
A26: Opening Cash | B26: 191449 | C26: =B27 -> 234782.33 | D26: =C27 -> 238115.67 | E26: =D27 -> 395141.39 | F26: =E27 -> 627367.63 | G26: =F27 -> 584787.24 | H26: =G27 -> 812502.35 | I26: =H27 -> 1065197 | J26: =I27 -> 1344081.6 | ... P26: =O27 -> 3756497
A27: Closing Cash | B27: =B26+B24 -> 234782.33 | C27: =C26+C24 -> 238115.67 | D27: =D26+D24 -> 395141.39 | E27: =E26+E24 -> 627367.63 | F27: =F26+F24 -> 584787.24 | G27: =G26+G24 -> 812502.35 | H27: =H26+H24 -> 1065197 | I27: =I26+I24 -> 1344081.6 | ... P27: =P26+P24 -> 4312836.3

Sheet Balance sheet
A1: BALANCE SHEET
A3: Metric | B3: 45931 | C3: 2026 | D3: 2027 | E3: 2028 | F3: 2029 | G3: 2030 | H3: 2031 | I3: 2032 | J3: 2033 | K3: 2034 | L3: 2035 | M3: 2036 | N3: 2037 | O3: 2038 | P3: 2039 | Q3: 2040
A4: ASSETS
A5: Cash | B5: =B8-B6-B7 -> 191449 | C5: ='Cash Flow'!B27 -> 234782.33 | D5: ='Cash Flow'!C27 -> 238115.67 | E5: ='Cash Flow'!D27 -> 395141.39 | F5: ='Cash Flow'!E27 -> 627367.63 | G5: ='Cash Flow'!F27 -> 584787.24 | H5: ='Cash Flow'!G27 -> 812502.35 | I5: ='Cash Flow'!H27 -> 1065197 | J5: ='Cash Flow'!I27 -> 1344081.6 | ... Q5: ='Cash Flow'!P27 -> 4312836.3
A6: Property & Buildings (Net) | B6: 155882 | C6: =B6+'Cash Flow'!B14*-1 -> 1305882 | D6: =C6+'Cash Flow'!C14*-1 -> 1555882 | E6: =D6+'Cash Flow'!D14*-1 -> 1605882 | F6: =E6+'Cash Flow'!E14*-1 -> 1655882 | G6: =F6+'Cash Flow'!F14*-1 -> 1705882 | H6: =G6+'Cash Flow'!G14*-1 -> 1755882 | I6: =H6+'Cash Flow'!H14*-1 -> 1805882 | J6: =I6+'Cash Flow'!I14*-1 -> 1855882 | ... Q6: =P6+'Cash Flow'!P14*-1 -> 2205882
A7: Other Assets | B7: 143772 | C7: =B7 -> 143772 | D7: =C7 -> 143772 | E7: =D7 -> 143772 | F7: =E7 -> 143772 | G7: =F7 -> 143772 | H7: =G7 -> 143772 | I7: =H7 -> 143772 | J7: =I7 -> 143772 | ... Q7: =P7 -> 143772
A8: TOTAL ASSETS | B8: 491103 | C8: =SUM(C5:C7) -> 1684436.3 | D8: =SUM(D5:D7) -> 1937769.7 | E8: =SUM(E5:E7) -> 2144795.4 | F8: =SUM(F5:F7) -> 2427021.6 | G8: =SUM(G5:G7) -> 2434441.2 | H8: =SUM(H5:H7) -> 2712156.4 | I8: =SUM(I5:I7) -> 3014851 | J8: =SUM(J5:J7) -> 3343735.6 | ... Q8: =SUM(Q5:Q7) -> 6662490.3
A10: LIABILITIES
A11: Bank Loans | B11: 0 | C11: ='Cash Flow'!B17+'Cash Flow'!B18 -> 653333.33 | D11: =C11+'Cash Flow'!C18 -> 606666.67 | E11: =D11+'Cash Flow'!D18 -> 560000 | F11: =E11+'Cash Flow'!E18 -> 513333.33 | G11: =F11+'Cash Flow'!F18 -> 466666.67 | H11: =G11+'Cash Flow'!G18 -> 420000 | I11: =H11+'Cash Flow'!H18 -> 373333.33 | J11: =I11+'Cash Flow'!I18 -> 326666.67 | K11: =J11+'Cash Flow'!J18 -> 280000 | ... Q11: =P11+'Cash Flow'!P18 -> 0
A12: Private Loans | B12: 363111 | C12: =B12+'Cash Flow'!B20+'Cash Flow'!B21 -> 763111 | D12: =C12+'Cash Flow'!C20+'Cash Flow'!C21 -> 763111 | E12: =D12+'Cash Flow'!D20+'Cash Flow'!D21 -> 500621.41 | F12: =E12+'Cash Flow'!E20+'Cash Flow'!E21 -> 350621.41 | G12: =F12+'Cash Flow'!F20+'Cash Flow'!F21 -> 100613.46 | H12: =G12+'Cash Flow'!G20+'Cash Flow'!G21 -> 100613.46 | I12: =H12+'Cash Flow'!H20+'Cash Flow'!H21 -> 100613.46 | J12: =I12+'Cash Flow'!I20+'Cash Flow'!I21 -> 100613.46 | ... Q12: =P12+'Cash Flow'!P20+'Cash Flow'!P21 -> 100613.46
A13: Other Liabilities | B13: 44792 | C13: =B13 -> 44792 | D13: =C13 -> 44792 | E13: =D13 -> 44792 | F13: =E13 -> 44792 | G13: =F13 -> 44792 | H13: =G13 -> 44792 | I13: =H13 -> 44792 | J13: =I13 -> 44792 | ... Q13: =P13 -> 44792
A14: TOTAL LIABILITIES | B14: =SUM(B11:B13) -> 407903 | C14: =SUM(C11:C13) -> 1461236.3 | D14: =SUM(D11:D13) -> 1414569.7 | E14: =SUM(E11:E13) -> 1105413.4 | F14: =SUM(F11:F13) -> 908746.74 | G14: =SUM(G11:G13) -> 612072.12 | H14: =SUM(H11:H13) -> 565405.46 | I14: =SUM(I11:I13) -> 518738.79 | ... Q14: =SUM(Q11:Q13) -> 145405.46
A16: EQUITY
A17: Share capital | B17: 249000 | C17: =B17+'Cash Flow'!B19 -> 399000 | D17: =C17+'Cash Flow'!C19 -> 649000 | E17: =D17+'Cash Flow'!D19 -> 899000 | F17: =E17+'Cash Flow'!E19 -> 1099000 | G17: =F17+'Cash Flow'!F19 -> 1099000 | H17: =G17+'Cash Flow'!G19 -> 1099000 | I17: =H17+'Cash Flow'!H19 -> 1099000 | J17: =I17+'Cash Flow'!I19 -> 1099000 | ... Q17: =P17+'Cash Flow'!P19 -> 1099000
A18: Retained Earnings | B18: -165800 | C18: =B18+'Cash Flow'!B8 -> -175800 | D18: =C18+'Cash Flow'!C8 -> -125800 | E18: =D18+'Cash Flow'!D8 -> 140381.98 | F18: =E18+'Cash Flow'!E8 -> 419274.88 | G18: =F18+'Cash Flow'!F8 -> 723369.12 | H18: =G18+'Cash Flow'!G8 -> 1047750.9 | I18: =H18+'Cash Flow'!H8 -> 1397112.2 | J18: =I18+'Cash Flow'!I8 -> 1772663.5 | ... Q18: =P18+'Cash Flow'!P8 -> 5418084.9
A19: TOTAL EQUITY | B19: =SUM(B17:B18) -> 83200 | C19: =SUM(C17:C18) -> 223200 | D19: =SUM(D17:D18) -> 523200 | E19: =SUM(E17:E18) -> 1039382 | F19: =SUM(F17:F18) -> 1518274.9 | G19: =SUM(G17:G18) -> 1822369.1 | H19: =SUM(H17:H18) -> 2146750.9 | I19: =SUM(I17:I18) -> 2496112.2 | ... Q19: =SUM(Q17:Q18) -> 6517084.9
A21: TOTAL LIAB + EQUITY | B21: 491103 | C21: =C14+C19 -> 1684436.3 | D21: =D14+D19 -> 1937769.7 | E21: =E14+E19 -> 2144795.4 | F21: =F14+F19 -> 2427021.6 | G21: =G14+G19 -> 2434441.2 | H21: =H14+H19 -> 2712156.4 | I21: =I14+I19 -> 3014851 | J21: =J14+J19 -> 3343735.6 | ... Q21: =Q14+Q19 -> 6662490.3
A23: Balance Check (should = 0) | B23: =B8-B19-B14 -> 0 | C23: =C8-C19-C14 -> 0 | D23: =D8-D19-D14 -> 0 | E23: =E8-E19-E14 -> 0 | F23: =F8-F19-F14 -> 0 | G23: =G8-G19-G14 -> 1.1641532e-10 | H23: =H8-H19-H14 -> 2.3283064e-10 | I23: =I8-I19-I14 -> 4.6566129e-10 | ... Q23: =Q8-Q19-Q14 -> -1.7462298e-10

Sheet Sensitivity
A1: TDF FINANCIAL MODEL - SENSITIVITY ANALYSIS
A2: Impact of Occupancy (±10%) and ADR (±15%) on Financial Performance
A4: BASE CASE ASSUMPTIONS (2028)
A5: Base Occupancy | B5: =Assumptions!B21 -> 0.55
A6: ADR High Season | B6: =Assumptions!B14 -> 165
A7: ADR Low Season | B7: =Assumptions!B15 -> 85
A8: Net ADR (after OTA) | B8: =Assumptions!B16 -> 138.33333
A9: Base Revenue | B9: =PL!B4 -> 652865.53
A10: Base EBITDA | B10: =PL!B10 -> 246350.98
A11: Base Cash (2028) | B11: 385726
A12: Base Cash (2030) | B12: 555424
A15: EBITDA SENSITIVITY MATRIX (€)
B17: ADR -15% | C17: ADR Base | D17: ADR +15%
A18: Occ -10% | B18: €158 057 | C18: €201 591 | D18: €245 126
A19: Occ Base | B19: €190 899 | C19: =B10 -> 246350.98 | D19: €277 968
A20: Occ +10% | B20: €223 741 | C20: €267 275 | D20: €310 810
A23: CASH POSITION 2030 SENSITIVITY MATRIX (€)
B25: ADR -15% | C25: ADR Base | D25: ADR +15%
A26: Occ -10% | B26: €364 482 | C26: €473 319 | D26: €582 156
A27: Occ Base | B27: €446 587 | C27: €555 424 | D27: €664 261
A28: Occ +10% | B28: €528 692 | C28: €637 529 | D28: €746 366
A31: EBITDA % CHANGE FROM BASE CASE
B33: ADR -15% | C33: ADR Base | D33: ADR +15%
A34: Occ -10% | B34: -32,6% | C34: -14,0% | D34: +4,6%
A35: Occ Base | B35: -18,6% | C35: 0,0% | D35: +18,6%
A36: Occ +10% | B36: -4,6% | C36: +14,0% | D36: +32,6%
A39: KEY INSIGHTS
A40: • Worst Case (-10% Occ, -15% ADR): EBITDA €158K (-33%), still positive
A41: • Best Case (+10% Occ, +15% ADR): EBITDA €311K (+33%)
A42: • Break-even maintained in ALL scenarios
A43: • Cash position remains positive even in worst case (€364K in 2030)
A44: • Model shows resilience to market downturns
A47: METHODOLOGY
A48: Revenue sensitivity: Commercial (58%) + Unique (18%) sensitive to both factors;
A49: Community (20%) sensitive to occupancy only; Other (3%) fixed.
A50: EBITDA assumes 60% variable margin on incremental revenue.
A51: Cash assumes 80% EBITDA conversion in year, cumulative effect for 2030.

Sheet Co-Housing
A1: CO-HOUSING EXPANSION
A3: VILLAGE COMPONENTS | D3: Cost | E3: Common pot
A5: Neighborhood 1: Earthpod Hill | C5: Size (m2)
A6: Earthpods | B6: 10 | C6: 60 | D6: =Assumptions!$B$63*C6*(1+Assumptions!B64) -> 150000 | E6: =D6 * Assumptions!$B$64 * B6 -> 375000 | G6: =B6*C6 -> 600 | H6: 50-70m2
A7: Farmhouse (Shared) | B7: 1 | C7: 240 | D7: 200000 | G7: =B7*C7 -> 240 | H7: Staff housing, kitchen, cafe, library
A9: Neighborhood 2: Townhouses
A10: Townhouses | B10: 13 | C10: 144 | D10: =Assumptions!$B$63*C10*(1+Assumptions!B64) -> 360000 | E10: =D10 * Assumptions!$B$64 * B10 -> 1170000 | G10: =B10*C10 -> 1872 | H10: Families, connected to Abela street
A12: Shared Facilities
A13: Education Center | B13: 1 | C13: 150 | D13: =Assumptions!$B$63*C13 -> 300000 | G13: =B13*C13 -> 150 | H13: Tech + regen ag, volunteer teachers
A14: Commercial Orchard | B14: 1 | C14: 6000 | D14: =G23 -> 150000 | G14: =B14*C14 -> 6000 | H14: Olives, almonds, figs
A16: FINANCIAL MODEL | E16: =SUM(E5:E15) -> 1545000
G17: Total | H17: Notes
A19: Capital Requirements
A20: Land Acquisition | B20: 1 | C20: 550000 | G20: =C20*B20 -> 550000 | H20: 25 hectares
A21: Water Infrastructure | B21: 1 | C21: 75000 | G21: =C21*B21 -> 75000 | H21: Lakes, swales, etc.
A22: Roads & Access | B22: 1 | C22: 50000 | G22: =C22*B22 -> 50000
A23: Orchard Development | B23: 6 | C23: 25000 | G23: =C23*B23 -> 150000 | H23: 6 ha food forest
A24: Farmhouse | B24: 1 | C24: 200000 | G24: =C24*B24 -> 200000
A25: Education center | B25: 1 | C25: 300000 | G25: =C25*B25 -> 300000
A26: Total Infrastructure | G26: =SUM(G20:G25) -> 1325000
A28: House Construction (Participant Funded)
A29: Earthpods (10 units) | B29: 10 | C29: =D6 / (1 + Assumptions!$B$64) -> 120000 | G29: =C29*B29 -> 1200000
A30: Townhouses (13 units) | B30: 13 | C30: =D10 / (1 + Assumptions!$B$64) -> 288000 | G30: =C30*B30 -> 3744000
A31: Total Participant Investment | G31: =SUM(G29:G30) -> 4944000 | H31: Hard construction budget
A32: Total investment | G32: =G31+G26 -> 6269000
A34: Recurring Revenue | C34: Monthly
A35: Utility Fees - Earthpods | B35: 10 | C35: 150 | G35: =C35*B35 -> 1500
A36: Utility Fees - Townhouses | B36: 13 | C36: 250 | G36: =C36*B36 -> 3250
A37: Annual Utility Revenue | G37: =SUM(G35:G36)*12 -> 57000

Sheet Cash Flow (+cohousing)
A1: CASH FLOW STATEMENT
A3: Metric | B3: 2026 | C3: 2027 | D3: 2028 | E3: 2029 | F3: 2030 | G3: 2031 | H3: 2032 | I3: 2033 | J3: 2034 | K3: 2035 | L3: 2036 | M3: 2037 | N3: 2038 | O3: 2039 | P3: 2040
A4: OPERATING ACTIVITIES
A5: Net Income | B5: 0 | C5: 0 | D5: =PL!B19 -> 188181.98 | E5: =PL!C19 -> 200892.9 | F5: =PL!D19 -> 234094.23 | G5: =PL!E19 -> 259381.77 | H5: =PL!F19 -> 289361.3 | I5: =PL!G19 -> 325551.32 | J5: =PL!H19 -> 360232.83 | K5: =PL!I19 -> 393601.3 | ... P5: =PL!N19 -> 608006.05
A6: Add: Depreciation | B6: 0 | C6: 0 | D6: 78000 | E6: 78000 | F6: 70000 | G6: 65000 | H6: 60000 | I6: 50000 | J6: 45000 | K6: 45000 | L6: 45000 | M6: 45000 | N6: 45000 | O6: 45000 | P6: 45000
A7: Working Capital Changes | B7: 0 | C7: 0 | D7: 0 | E7: 0 | F7: 0 | G7: 0 | H7: 0 | I7: 0 | J7: 0 | K7: 0 | L7: 0 | M7: 0 | N7: 0 | O7: 0 | P7: 0
A8: Operating Cash Flow | B8: =SUM(B5:B7) -> 0 | C8: =SUM(C5:C7) -> 0 | D8: =SUM(D5:D7) -> 266181.98 | E8: =SUM(E5:E7) -> 278892.9 | F8: =SUM(F5:F7) -> 304094.23 | G8: =SUM(G5:G7) -> 324381.77 | H8: =SUM(H5:H7) -> 349361.3 | I8: =SUM(I5:I7) -> 375551.32 | ... P8: =SUM(P5:P7) -> 653006.05
A10: INVESTING ACTIVITIES
A11: Building Purchase (from Sam) | B11: -200000 | C11: 0 | D11: 0 | E11: 0 | F11: 0 | G11: 0 | H11: 0 | I11: 0 | J11: 0 | K11: 0 | L11: 0 | M11: 0 | N11: 0 | O11: 0 | P11: 0
A12: Construction CapEx | B12: -800000 | C12: -250000 | D12: -50000 | E12: -50000 | F12: -50000 | G12: -50000 | H12: -50000 | I12: -50000 | J12: -50000 | K12: -50000 | L12: -50000 | M12: -50000 | N12: -50000 | O12: -50000 | P12: -50000
A13: Equipment & FF&E | B13: -50000 | C13: -100000 | D13: 0 | E13: 0 | F13: 0 | G13: 0 | H13: 0 | I13: 0 | J13: 0 | K13: 0 | L13: 0 | M13: 0 | N13: 0 | O13: 0 | P13: 0
A14: Co-Housing Commons | B14: =-'Co-Housing'!G20-50000 -> -600000 | C14: =-'Co-Housing'!G21-'Co-Housing'!G24 -> -275000 | D14: =-'Co-Housing'!G23/2-'Co-Housing'!G22 -> -125000 | E14: =-'Co-Housing'!$G$25/2 -> -150000 | F14: 0 | G14: =-'Co-Housing'!$G$25/2 -> -150000 | H14: 0 | I14: 0 | J14: 0 | K14: 0 | L14: 0 | M14: 0 | N14: 0 | O14: 0 | P14: 0
A15: Co-Housing Houses | C15: =-('Co-Housing'!$G$31)/3 -> -1648000 | D15: =D22*-1 -> -3826000
A16: Investing Cash Flow | B16: =Sum(B11:B15) -> -1650000 | C16: =Sum(C11:C15) -> -2273000 | D16: =Sum(D11:D15) -> -4001000 | E16: =Sum(E11:E15) -> -200000 | F16: =Sum(F11:F15) -> -50000 | G16: =Sum(G11:G15) -> -200000 | H16: =Sum(H11:H15) -> -50000 | I16: =Sum(I11:I15) -> -50000 | ... P16: =Sum(P11:P15) -> -50000
A18: FINANCING ACTIVITIES
A19: Bank Loan Drawdown | B19: ='Debt Stack'!C19 -> 700000 | C19: 0 | I19: 0 | J19: 0 | K19: 0 | L19: 0 | M19: 0 | N19: 0 | O19: 0 | P19: 0
A20: Bank Loan Principal | B20: ='Debt Stack'!C20 -> -46666.667 | C20: =-$B$19/15 -> -46666.667 | D20: =-$B$19/15-$D$19/15 -> -46666.667 | E20: =-$B$19/15-$D$19/15 -> -46666.667 | F20: =-$B$19/15-$D$19/15 -> -46666.667 | G20: =-$B$19/15-$D$19/15 -> -46666.667 | H20: =-$B$19/15-$D$19/15 -> -46666.667 | I20: =-$B$19/15-$D$19/15 -> -46666.667 | J20: =-$B$19/15-$D$19/15 -> -46666.667 | K20: =-$B$19/15-$D$19/15 -> -46666.667 | ... P20: =-$B$19/15-$D$19/15 -> -46666.667
A21: Equity injection from token proceeds | B21: 150000 | C21: 250000 | D21: 250000 | E21: 150000 | F21: 100000 | G21: 0 | H21: 0 | I21: 0 | J21: 0 | K21: 0 | L21: 0 | M21: 0 | N21: 0 | O21: 0 | P21: 0
A22: Equity injection from token proceeds (cohousing) | B22: 0 | C22: =('Co-Housing'!$G$31+'Co-Housing'!$E$16)/3 -> 2163000 | D22: =('Co-Housing'!$G$31+'Co-Housing'!$E$16)/3*2-'Debt Stack'!C39 -> 3826000
A23: Private Loan | B23: ='Debt Stack'!C32 -> 450000
A24: Private Loan Principal | B24: ='Debt Stack'!C49 -> -50000 | C24: ='Debt Stack'!D49 -> 0 | D24: ='Debt Stack'!E49 -> -262489.59 | E24: ='Debt Stack'!F49 -> -150000 | F24: ='Debt Stack'!G49 -> -250007.95 | G24: ='Debt Stack'!H49 -> 0 | H24: ='Debt Stack'!I49 -> 0 | I24: ='Debt Stack'!J49 -> 0 | ... P24: ='Debt Stack'!Q49 -> 0
A25: Co-housing Deposits | B25: ='Debt Stack'!C39 -> 500000
A26: Financing Cash Flow | B26: =SUM(B19:B25) -> 1703333.3 | C26: =SUM(C19:C25) -> 2366333.3 | D26: =SUM(D19:D25) -> 3766843.7 | E26: =SUM(E19:E25) -> -46666.667 | F26: =SUM(F19:F25) -> -196674.62 | G26: =SUM(G19:G25) -> -46666.667 | H26: =SUM(H19:H25) -> -46666.667 | I26: =SUM(I19:I25) -> -46666.667 | ... P26: =SUM(P19:P25) -> -46666.667
A28: NET CASH FLOW | B28: =B26+B16+B8 -> 53333.333 | C28: =C26+C16+C8 -> 93333.333 | D28: =D26+D16+D8 -> 32025.725 | E28: =E26+E16+E8 -> 32226.236 | F28: =F26+F16+F8 -> 57419.615 | G28: =G26+G16+G8 -> 77715.108 | H28: =H26+H16+H8 -> 252694.63 | I28: =I26+I16+I8 -> 278884.65 | ... P28: =P26+P16+P8 -> 556339.38
A30: Opening Cash | B30: 191449 | C30: =B31 -> 244782.33 | D30: =C31 -> 338115.67 | E30: =D31 -> 370141.39 | F30: =E31 -> 402367.63 | G30: =F31 -> 459787.24 | H30: =G31 -> 537502.35 | I30: =H31 -> 790196.98 | J30: =I31 -> 1069081.6 | ... P30: =O31 -> 3481497
A31: Closing Cash | B31: =B30+B28 -> 244782.33 | C31: =C30+C28 -> 338115.67 | D31: =D30+D28 -> 370141.39 | E31: =E30+E28 -> 402367.63 | F31: =F30+F28 -> 459787.24 | G31: =G30+G28 -> 537502.35 | H31: =H30+H28 -> 790196.98 | I31: =I30+I28 -> 1069081.6 | ... P31: =P30+P28 -> 4037836.3

Sheet Balance sheet (+cohousing)
A1: BALANCE SHEET (including co-housing)
A3: Metric | B3: 45931 | C3: 2026 | D3: 2027 | E3: 2028 | F3: 2029 | G3: 2030 | H3: 2031 | I3: 2032 | J3: 2033 | K3: 2034 | L3: 2035 | M3: 2036 | N3: 2037 | O3: 2038 | P3: 2039 | Q3: 2040
A4: ASSETS
A5: Cash | B5: =B8-B6-B7 -> 191449 | C5: ='Cash Flow (+cohousing)'!B31 -> 244782.33 | D5: ='Cash Flow (+cohousing)'!C31 -> 338115.67 | E5: ='Cash Flow (+cohousing)'!D31 -> 370141.39 | F5: ='Cash Flow (+cohousing)'!E31 -> 402367.63 | G5: ='Cash Flow (+cohousing)'!F31 -> 459787.24 | H5: ='Cash Flow (+cohousing)'!G31 -> 537502.35 | I5: ='Cash Flow (+cohousing)'!H31 -> 790196.98 | J5: ='Cash Flow (+cohousing)'!I31 -> 1069081.6 | ... Q5: ='Cash Flow (+cohousing)'!P31 -> 4037836.3
A6: Property & Buildings (Net) | B6: 155882 | C6: =B6+'Cash Flow (+cohousing)'!B16*-1 -> 1805882 | D6: =C6+'Cash Flow (+cohousing)'!C16*-1 -> 4078882 | E6: =D6+'Cash Flow (+cohousing)'!D16*-1 -> 8079882 | F6: =E6+'Cash Flow (+cohousing)'!E16*-1 -> 8279882 | G6: =F6+'Cash Flow (+cohousing)'!F16*-1 -> 8329882 | H6: =G6+'Cash Flow (+cohousing)'!G16*-1 -> 8529882 | I6: =H6+'Cash Flow (+cohousing)'!H16*-1 -> 8579882 | J6: =I6+'Cash Flow (+cohousing)'!I16*-1 -> 8629882 | ... Q6: =P6+'Cash Flow (+cohousing)'!P16*-1 -> 8979882
A7: Other Assets | B7: 143772 | C7: =B7 -> 143772 | D7: =C7 -> 143772 | E7: =D7 -> 143772 | F7: =E7 -> 143772 | G7: =F7 -> 143772 | H7: =G7 -> 143772 | I7: =H7 -> 143772 | J7: =I7 -> 143772 | ... Q7: =P7 -> 143772
A8: TOTAL ASSETS | B8: 491103 | C8: =SUM(C5:C7) -> 2194436.3 | D8: =SUM(D5:D7) -> 4560769.7 | E8: =SUM(E5:E7) -> 8593795.4 | F8: =SUM(F5:F7) -> 8826021.6 | G8: =SUM(G5:G7) -> 8933441.2 | H8: =SUM(H5:H7) -> 9211156.3 | I8: =SUM(I5:I7) -> 9513851 | J8: =SUM(J5:J7) -> 9842735.6 | ... Q8: =SUM(Q5:Q7) -> 13161490
A10: LIABILITIES
A11: Bank Loans | B11: 0 | C11: ='Debt Stack'!C22 -> 653333.33 | D11: ='Debt Stack'!D22 -> 606666.67 | E11: ='Debt Stack'!E22 -> 560000 | F11: ='Debt Stack'!F22 -> 513333.33 | G11: ='Debt Stack'!G22 -> 466666.67 | H11: ='Debt Stack'!H22 -> 420000 | I11: ='Debt Stack'!I22 -> 373333.33 | J11: ='Debt Stack'!J22 -> 326666.67 | ... Q11: ='Debt Stack'!Q22 -> 0
A12: Private Loans | B12: 363111 | C12: ='Debt Stack'!C29+'Debt Stack'!C36 -> 731028.77 | D12: ='Debt Stack'!D29+'Debt Stack'!D36 -> 672750.78 | E12: ='Debt Stack'!E29+'Debt Stack'!E36 -> 393431.25 | F12: ='Debt Stack'!F29+'Debt Stack'!F36 -> 238102.81 | G12: ='Debt Stack'!G29+'Debt Stack'!G36 -> 0 | H12: ='Debt Stack'!H29+'Debt Stack'!H36 -> 0 | I12: ='Debt Stack'!I29+'Debt Stack'!I36 -> 0 | J12: ='Debt Stack'!J29+'Debt Stack'!J36 -> 0 | ... Q12: ='Debt Stack'!Q29+'Debt Stack'!Q36 -> 0
A13: Co-housing Deposits | B13: 0 | C13: ='Debt Stack'!C43 -> 460000 | D13: ='Debt Stack'!D43 -> 219200 | E13: ='Debt Stack'!E43 -> 0 | F13: ='Debt Stack'!F43 -> 0 | G13: ='Debt Stack'!G43 -> 0 | H13: ='Debt Stack'!H43 -> 0 | I13: ='Debt Stack'!I43 -> 0 | J13: ='Debt Stack'!J43 -> 0 | ... Q13: ='Debt Stack'!Q43 -> 0
A14: Other Liabilities | B14: 44792 | C14: =B14 -> 44792 | D14: =C14 -> 44792 | E14: =D14 -> 44792 | F14: =E14 -> 44792 | G14: =F14 -> 44792 | H14: =G14 -> 44792 | I14: =H14 -> 44792 | J14: =I14 -> 44792 | ... Q14: =P14 -> 44792
A15: TOTAL LIABILITIES | B15: =SUM(B11:B14) -> 407903 | C15: =SUM(C11:C14) -> 1889154.1 | D15: =SUM(D11:D14) -> 1543409.5 | E15: =SUM(E11:E14) -> 998223.25 | F15: =SUM(F11:F14) -> 796228.15 | G15: =SUM(G11:G14) -> 511458.67 | H15: =SUM(H11:H14) -> 464792 | I15: =SUM(I11:I14) -> 418125.33 | ... Q15: =SUM(Q11:Q14) -> 44792
A17: EQUITY
A18: Share capital | B18: 249000 | C18: =B18+'Cash Flow (+cohousing)'!B21+'Cash Flow (+cohousing)'!B22-('Debt Stack'!C27+'Debt Stack'!C34+'Debt Stack'!C41) -> 529000 | D18: =C18+'Cash Flow (+cohousing)'!C21+'Cash Flow (+cohousing)'!C22-('Debt Stack'!D27+'Debt Stack'!D34+'Debt Stack'!D41) -> 3292000 | E18: =D18+'Cash Flow (+cohousing)'!D21+'Cash Flow (+cohousing)'!D22-('Debt Stack'!E27+'Debt Stack'!E34+'Debt Stack'!E41) -> 7646584 | F18: =E18+'Cash Flow (+cohousing)'!E21+'Cash Flow (+cohousing)'!E22-('Debt Stack'!F27+'Debt Stack'!F34+'Debt Stack'!F41) -> 7821584 | G18: =F18+'Cash Flow (+cohousing)'!F21+'Cash Flow (+cohousing)'!F22-('Debt Stack'!G27+'Debt Stack'!G34+'Debt Stack'!G41) -> 7921584 | H18: =G18+'Cash Flow (+cohousing)'!G21+'Cash Flow (+cohousing)'!G22-('Debt Stack'!H27+'Debt Stack'!H34+'Debt Stack'!H41) -> 7921584 | I18: =H18+'Cash Flow (+cohousing)'!H21+'Cash Flow (+cohousing)'!H22-('Debt Stack'!I27+'Debt Stack'!I34+'Debt Stack'!I41) -> 7921584 | J18: =I18+'Cash Flow (+cohousing)'!I21+'Cash Flow (+cohousing)'!I22-('Debt Stack'!J27+'Debt Stack'!J34+'Debt Stack'!J41) -> 7921584 | ... Q18: =P18+'Cash Flow (+cohousing)'!P21+'Cash Flow (+cohousing)'!P22-('Debt Stack'!Q27+'Debt Stack'!Q34+'Debt Stack'!Q41) -> 7921584
A19: Retained Earnings | B19: -165800 | C19: =B19+'Cash Flow (+cohousing)'!B8-('Debt Stack'!C26+'Debt Stack'!C33+'Debt Stack'!C40) -> -223717.77 | D19: =C19+'Cash Flow (+cohousing)'!C8-('Debt Stack'!D26+'Debt Stack'!D33+'Debt Stack'!D40) -> -274639.78 | E19: =D19+'Cash Flow (+cohousing)'!D8-('Debt Stack'!E26+'Debt Stack'!E33+'Debt Stack'!E40) -> -51011.859 | F19: =E19+'Cash Flow (+cohousing)'!E8-('Debt Stack'!F26+'Debt Stack'!F33+'Debt Stack'!F40) -> 208209.48 | G19: =F19+'Cash Flow (+cohousing)'!F8-('Debt Stack'!G26+'Debt Stack'!G33+'Debt Stack'!G40) -> 500398.58 | H19: =G19+'Cash Flow (+cohousing)'!G8-('Debt Stack'!H26+'Debt Stack'!H33+'Debt Stack'!H40) -> 824780.35 | I19: =H19+'Cash Flow (+cohousing)'!H8-('Debt Stack'!I26+'Debt Stack'!I33+'Debt Stack'!I40) -> 1174141.6 | J19: =I19+'Cash Flow (+cohousing)'!I8-('Debt Stack'!J26+'Debt Stack'!J33+'Debt Stack'!J40) -> 1549693 | ... Q19: =P19+'Cash Flow (+cohousing)'!P8-('Debt Stack'!Q26+'Debt Stack'!Q33+'Debt Stack'!Q40) -> 5195114.3
A20: TOTAL EQUITY | B20: =SUM(B18:B19) -> 83200 | C20: =SUM(C18:C19) -> 305282.23 | D20: =SUM(D18:D19) -> 3017360.2 | E20: =SUM(E18:E19) -> 7595572.1 | F20: =SUM(F18:F19) -> 8029793.5 | G20: =SUM(G18:G19) -> 8421982.6 | H20: =SUM(H18:H19) -> 8746364.3 | I20: =SUM(I18:I19) -> 9095725.6 | ... Q20: =SUM(Q18:Q19) -> 13116698
A22: TOTAL LIAB + EQUITY | B22: 491103 | C22: =C15+C20 -> 2194436.3 | D22: =D15+D20 -> 4560769.7 | E22: =E15+E20 -> 8593795.4 | F22: =F15+F20 -> 8826021.6 | G22: =G15+G20 -> 8933441.2 | H22: =H15+H20 -> 9211156.3 | I22: =I15+I20 -> 9513851 | J22: =J15+J20 -> 9842735.6 | ... Q22: =Q15+Q20 -> 13161490
A24: Balance Check (should = 0) | B24: =B8-B20-B15 -> 0 | C24: =C8-C20-C15 -> 2.3283064e-10 | D24: =D8-D20-D15 -> 4.6566129e-10 | E24: =E8-E20-E15 -> 8.1490725e-10 | F24: =F8-F20-F15 -> -4.6566129e-10 | G24: =G8-G20-G15 -> 1.1641532e-09 | H24: =H8-H20-H15 -> 0 | I24: =I8-I20-I15 -> 5.8207661e-10 | ... Q24: =Q8-Q20-Q15 -> 0
